<?xml version="1.0" encoding="utf-8"?>
<!-- This URDF was automatically created by SolidWorks to URDF Exporter! Originally created by Stephen Brawner (brawner@gmail.com) 
     Commit Version: 1.6.0-4-g7f85cfe  Build Version: 1.6.7995.38578
     For more information, please see http://wiki.ros.org/sw_urdf_exporter -->
<robot
  name="xarm_urdf_color">
  <link
    name="base_link">
    <inertial>
      <origin
        xyz="-0.024415 0.015635 0.090248"
        rpy="0 0 0" />
      <mass
        value="1.1181" />
      <inertia
        ixx="0.001685"
        ixy="1.6957E-06"
        ixz="9.2957E-07"
        iyy="0.0016671"
        iyz="-9.0262E-06"
        izz="0.0013787" />
    </inertial>
    <visual>
      <origin
        xyz="0 0 0"
        rpy="0 0 0" />
      <geometry>
        <mesh
          filename="package://xarm_urdf_color/meshes/base_link.STL" />
      </geometry>
      <material
        name="">
        <color
          rgba="0.5 1 1 1" />
      </material>
    </visual>
    <collision>
      <origin
        xyz="0 0 0"
        rpy="0 0 0" />
      <geometry>
        <mesh
          filename="package://xarm_urdf_color/meshes/base_link.STL" />
      </geometry>
    </collision>
  </link>
  <link
    name="Link2">
    <inertial>
      <origin
        xyz="8.1362E-08 0.0034088 0.086994"
        rpy="0 0 0" />
      <mass
        value="1.3381" />
      <inertia
        ixx="0.0030614"
        ixy="6.6429E-10"
        ixz="-5.6484E-07"
        iyy="0.0032341"
        iyz="0.00016586"
        izz="0.0014021" />
    </inertial>
    <visual>
      <origin
        xyz="0 0 0"
        rpy="0 0 0" />
      <geometry>
        <mesh
          filename="package://xarm_urdf_color/meshes/Link2.STL" />
      </geometry>
      <material
        name="">
        <color
          rgba="1 0.5 1 1" />
      </material>
    </visual>
    <collision>
      <origin
        xyz="0 0 0"
        rpy="0 0 0" />
      <geometry>
        <mesh
          filename="package://xarm_urdf_color/meshes/Link2.STL" />
      </geometry>
    </collision>
  </link>
  <joint
    name="joint2"
    type="continuous">
    <origin
      xyz="-0.02444 0.015911 0.16646"
      rpy="0 0 1.5708" />
    <parent
      link="base_link" />
    <child
      link="Link2" />
    <axis
      xyz="0 0 1" />
    <limit
      lower="0"
      upper="0"
      effort="0"
      velocity="0" />
  </joint>
  <link
    name="Link3">
    <inertial>
      <origin
        xyz="0.012168 -0.15565 -0.035665"
        rpy="0 0 0" />
      <mass
        value="2.8892" />
      <inertia
        ixx="0.032819"
        ixy="0.0033762"
        ixz="0.0012993"
        iyy="0.010159"
        iyz="-0.010876"
        izz="0.027588" />
    </inertial>
    <visual>
      <origin
        xyz="0 0 0"
        rpy="0 0 0" />
      <geometry>
        <mesh
          filename="package://xarm_urdf_color/meshes/Link3.STL" />
      </geometry>
      <material
        name="">
        <color
          rgba="1 1 0.5 1" />
      </material>
    </visual>
    <collision>
      <origin
        xyz="0 0 0"
        rpy="0 0 0" />
      <geometry>
        <mesh
          filename="package://xarm_urdf_color/meshes/Link3.STL" />
      </geometry>
    </collision>
  </link>
  <joint
    name="joint3"
    type="revolute">
    <origin
      xyz="0 0.0621 0.118"
      rpy="-1.5708 0 0" />
    <parent
      link="Link2" />
    <child
      link="Link3" />
    <axis
      xyz="0 0 1" />
    <limit
      lower="-2.0595"
      upper="2.0944"
      effort="0"
      velocity="0" />
  </joint>
  <link
    name="Link4">
    <inertial>
      <origin
        xyz="0.05723 0.071725 -0.003541"
        rpy="0 0 0" />
      <mass
        value="1.559" />
      <inertia
        ixx="0.0048668"
        ixy="-0.0016529"
        ixz="0.0009458"
        iyy="0.0045374"
        iyz="0.0011458"
        izz="0.0048084" />
    </inertial>
    <visual>
      <origin
        xyz="0 0 0"
        rpy="0 0 0" />
      <geometry>
        <mesh
          filename="package://xarm_urdf_color/meshes/Link4.STL" />
      </geometry>
      <material
        name="">
        <color
          rgba="0.5 0.5 1 1" />
      </material>
    </visual>
    <collision>
      <origin
        xyz="0 0 0"
        rpy="0 0 0" />
      <geometry>
        <mesh
          filename="package://xarm_urdf_color/meshes/Link4.STL" />
      </geometry>
    </collision>
  </link>
  <joint
    name="joint4"
    type="revolute">
    <origin
      xyz="0.053148 -0.28478 -0.0178"
      rpy="0 0 0" />
    <parent
      link="Link3" />
    <child
      link="Link4" />
    <axis
      xyz="0 0 1" />
    <limit
      lower="-3.927"
      upper="0.19199"
      effort="0"
      velocity="0" />
  </joint>
  <link
    name="Link5">
    <inertial>
      <origin
        xyz="-5.3149E-07 0.030899 0.10125"
        rpy="0 0 0" />
      <mass
        value="0.84286" />
      <inertia
        ixx="0.0046465"
        ixy="2.6629E-10"
        ixz="-1.2154E-09"
        iyy="0.0041624"
        iyz="-0.001225"
        izz="0.0011818" />
    </inertial>
    <visual>
      <origin
        xyz="0 0 0"
        rpy="0 0 0" />
      <geometry>
        <mesh
          filename="package://xarm_urdf_color/meshes/Link5.STL" />
      </geometry>
      <material
        name="">
        <color
          rgba="0.5 1 0.5 1" />
      </material>
    </visual>
    <collision>
      <origin
        xyz="0 0 0"
        rpy="0 0 0" />
      <geometry>
        <mesh
          filename="package://xarm_urdf_color/meshes/Link5.STL" />
      </geometry>
    </collision>
  </link>
  <joint
    name="joint5"
    type="continuous">
    <origin
      xyz="0.077749 0.16061 -0.0443"
      rpy="-1.5708 0 0" />
    <parent
      link="Link4" />
    <child
      link="Link5" />
    <axis
      xyz="0 0 1" />
    <limit
      lower="0"
      upper="0"
      effort="0"
      velocity="0" />
  </joint>
  <link
    name="Link6">
    <inertial>
      <origin
        xyz="0.045987 0.0093462 0.022466"
        rpy="0 0 0" />
      <mass
        value="0.82753" />
      <inertia
        ixx="0.00064253"
        ixy="-2.4535E-05"
        ixz="0.00022583"
        iyy="0.0015836"
        iyz="7.043E-06"
        izz="0.0015057" />
    </inertial>
    <visual>
      <origin
        xyz="0 0 0"
        rpy="0 0 0" />
      <geometry>
        <mesh
          filename="package://xarm_urdf_color/meshes/Link6.STL" />
      </geometry>
      <material
        name="">
        <color
          rgba="1 0.5 0.5 1" />
      </material>
    </visual>
    <collision>
      <origin
        xyz="0 0 0"
        rpy="0 0 0" />
      <geometry>
        <mesh
          filename="package://xarm_urdf_color/meshes/Link6.STL" />
      </geometry>
    </collision>
  </link>
  <joint
    name="joint6"
    type="revolute">
    <origin
      xyz="1.1469E-05 0.014 0.1817"
      rpy="1.5708 0 0" />
    <parent
      link="Link5" />
    <child
      link="Link6" />
    <axis
      xyz="0 0 1" />
    <limit
      lower="-1.693"
      upper="3.1416"
      effort="0"
      velocity="0" />
  </joint>
  <link
    name="EE_Link">
    <inertial>
      <origin
        xyz="1.59805922494982E-07 -0.00180149622908889 0.0156188075371726"
        rpy="0 0 0" />
      <mass
        value="0.138708669532972" />
      <inertia
        ixx="6.96057927162632E-05"
        ixy="9.5724766077616E-10"
        ixz="8.28562698985609E-12"
        iyy="5.83956362885756E-05"
        iyz="-2.90543034249767E-07"
        izz="0.000108805105179939" />
    </inertial>
    <visual>
      <origin
        xyz="0 0 0"
        rpy="0 0 0" />
      <geometry>
        <mesh
          filename="package://xarm_urdf_color/meshes/EE_Link.STL" />
      </geometry>
      <material
        name="">
        <color
          rgba="1 1 1 1" />
      </material>
    </visual>
    <collision>
      <origin
        xyz="0 0 0"
        rpy="0 0 0" />
      <geometry>
        <mesh
          filename="package://xarm_urdf_color/meshes/EE_Link.STL" />
      </geometry>
    </collision>
  </link>
  <joint
    name="joint7"
    type="continuous">
    <origin
      xyz="0.075889 0.063504 0.014"
      rpy="-1.5708 0 0" />
    <parent
      link="Link6" />
    <child
      link="EE_Link" />
    <axis
      xyz="0 0 1" />
    <limit
      lower="0"
      upper="0"
      effort="0"
      velocity="0" />
  </joint>
</robot>